<sdf version='1.6'>
  <model name="swift_pico">
    <pose>0 0 0 0 0 0</pose>
    <link name='swift_pico/base_link'>
      <pose frame=''>0 0 0 0 -0 0</pose>
      <inertial>
        <pose frame=''>0 0 0 0 -0 0</pose>
        <mass>1.5</mass>
        <inertia>
          <ixx>0.0347563</ixx>
          <ixy>0</ixy>
          <ixz>0</ixz>
          <iyy>0.07</iyy>
          <iyz>0</iyz>
          <izz>0.0977</izz>
        </inertia>
      </inertial>
      <collision name='swift_pico/base_link_inertia_collision'>
        <pose frame=''>0 0 -0.12 0 -0 0</pose>
        <geometry>
          <box>
            <size>0.47 0.47 0.11</size>
          </box>
        </geometry>
      </collision>
      <visual name='swift_pico/base_link_inertia_visual'>
        <pose frame=''>0 0 0 0 -0 0</pose>
        <geometry>
          <mesh>
            <scale>5 5 5</scale>
            <uri>model://swift_pico/meshes/base_link.dae</uri>
          </mesh>
        </geometry>
        <material>
            <ambient>0 0 0 1</ambient>
            <diffuse>0 0 0 1</diffuse>
            <specular>0 0 0 1</specular>
          </material>
      </visual>
    </link>

    <link name="marker_link">
        <pose frame=''>0 0 0 0 -0 0</pose>
        <inertial>
        <mass>0.1</mass>
        <inertia>
          <ixx>1.66e-06</ixx>
          <ixy>0</ixy>
          <ixz>0</ixz>
          <iyy>1.66e-06</iyy>
          <iyz>0</iyz>
          <izz>1.66e-06</izz>
        </inertia>
      </inertial>
				<visual name='Whycon_Marker'>
					<pose>0.0 0 0 1.57 0 0</pose>
					<geometry>
            <mesh>
              <scale>0.5 0.5 0.5</scale>
              <uri>model://swift_pico/meshes/whycon2.obj</uri>
            </mesh>
					</geometry>
				</visual>
			</link>

    <joint name="marker_joint" type="fixed">

      <child>marker_link</child>
      <parent>swift_pico/base_link</parent>
		</joint>

    <link name='swift_pico/m1'>
      <pose frame=''>0.19 -0.19 -0.12 0 -0 0</pose>
      <inertial>
        <pose frame=''>0 0 0.1 0 -0 0</pose>
        <mass>0.005</mass>
        <inertia>
          <ixx>9.75e-07</ixx>
          <ixy>0</ixy>
          <ixz>0</ixz>
          <iyy>4.17041e-05</iyy>
          <iyz>0</iyz>
          <izz>4.26041e-05</izz>
        </inertia>
      </inertial>
      <collision name='swift_pico/m1_collision'>
        <pose frame=''>0 0 0.1 0 -0 0</pose>
        <geometry>
          <cylinder>
            <length>0.005</length>
            <radius>0.1</radius>
          </cylinder>
        </geometry>
        <surface>
          <contact>
            <ode/>
          </contact>
          <friction>
            <ode/>
          </friction>
        </surface>
      </collision>
      <visual name='swift_pico/m1_visual'>
        <pose frame=''>0 0 0.1 0 -0 0</pose>
        <geometry>
          <mesh>
            <scale>5 5 5</scale>
            <uri>model://swift_pico/meshes/m1_link.dae</uri>
          </mesh>
        </geometry>
        <material>
            <ambient>1 0 1 1</ambient>
            <diffuse>1 0 1 1</diffuse>
            <specular>1 0 1 1</specular>
          </material>
      </visual>
      <gravity>1</gravity>
      <velocity_decay/>
    </link>
    <joint name='swift_pico/m1_joint' type='revolute'>
      <child>swift_pico/m1</child>
      <parent>swift_pico/base_link</parent>
      <axis>
        <xyz>0 0 1</xyz>
        <limit>
          <lower>-1e+16</lower>
          <upper>1e+16</upper>
        </limit>
        <dynamics>
          <spring_reference>0</spring_reference>
          <spring_stiffness>0</spring_stiffness>
        </dynamics>
        <use_parent_model_frame>1</use_parent_model_frame>
      </axis>
    </joint>
    <link name='swift_pico/m2'>
      <pose frame=''>-0.19 0.19 -0.12 0 -0 0</pose>
      <inertial>
        <pose frame=''>0 0 0.1 0 -0 0</pose>
        <mass>0.005</mass>
        <inertia>
          <ixx>9.75e-07</ixx>
          <ixy>0</ixy>
          <ixz>0</ixz>
          <iyy>4.17041e-05</iyy>
          <iyz>0</iyz>
          <izz>4.26041e-05</izz>
        </inertia>
      </inertial>
      <collision name='swift_pico/m2_collision'>
        <pose frame=''>0 0 0.1 0 -0 0</pose>
        <geometry>
          <cylinder>
            <length>0.005</length>
            <radius>0.1</radius>
          </cylinder>
        </geometry>
        <surface>
          <contact>
            <ode/>
          </contact>
          <friction>
            <ode/>
          </friction>
        </surface>
      </collision>
      <visual name='swift_pico/m2_visual'>
        <pose frame=''>0 0 0.1 0 -0 0</pose>
        <geometry>
          <mesh>
            <scale>5 5 5</scale>
            <uri>model://swift_pico/meshes/m1_link.dae</uri>
          </mesh>
        </geometry>
        <material>
            <ambient>1 0 0 1</ambient>
            <diffuse>1 0 0 1</diffuse>
            <specular>1 0 0 1</specular>
          </material>
      </visual>
      <gravity>1</gravity>
      <velocity_decay/>
    </link>
    <joint name='swift_pico/m2_joint' type='revolute'>
      <child>swift_pico/m2</child>
      <parent>swift_pico/base_link</parent>
      <axis>
        <xyz>0 0 1</xyz>
        <limit>
          <lower>-1e+16</lower>
          <upper>1e+16</upper>
        </limit>
        <dynamics>
          <spring_reference>0</spring_reference>
          <spring_stiffness>0</spring_stiffness>
        </dynamics>
        <use_parent_model_frame>1</use_parent_model_frame>
      </axis>
    </joint>
    <link name='swift_pico/m3'>
      <pose frame=''>0.19 0.19 -0.12 0 -0 0</pose>
      <inertial>
        <pose frame=''>0 0 0.1 0 -0 0</pose>
        <mass>0.005</mass>
        <inertia>
          <ixx>9.75e-07</ixx>
          <ixy>0</ixy>
          <ixz>0</ixz>
          <iyy>4.17041e-05</iyy>
          <iyz>0</iyz>
          <izz>4.26041e-05</izz>
        </inertia>
      </inertial>
      <collision name='swift_pico/m3_collision'>
        <pose frame=''>0 0 0.1 0 -0 0</pose>
        <geometry>
          <cylinder>
            <length>0.005</length>
            <radius>0.1</radius>
          </cylinder>
        </geometry>
        <surface>
          <contact>
            <ode/>
          </contact>
          <friction>
            <ode/>
          </friction>
        </surface>
      </collision>
      <visual name='swift_pico/m3_visual'>
        <pose frame=''>0 0 0.1 0 -0 0</pose>
        <geometry>
          <mesh>
            <scale>5 5 5</scale>
            <uri>model://swift_pico/meshes/m4_link.dae</uri>
          </mesh>
        </geometry>
        <material>
            <ambient>1 0 1 1</ambient>
            <diffuse>1 0 1 1</diffuse>
            <specular>1 0 1 1</specular>
          </material>
      </visual>
      <gravity>1</gravity>
      <velocity_decay/>
    </link>
    <joint name='swift_pico/m3_joint' type='revolute'>
      <child>swift_pico/m3</child>
      <parent>swift_pico/base_link</parent>
      <axis>
        <xyz>0 0 1</xyz>
        <limit>
          <lower>-1e+16</lower>
          <upper>1e+16</upper>
        </limit>
        <dynamics>
          <spring_reference>0</spring_reference>
          <spring_stiffness>0</spring_stiffness>
        </dynamics>
        <use_parent_model_frame>1</use_parent_model_frame>
      </axis>
    </joint>
    <link name='swift_pico/m4'>
      <pose frame=''>-0.19 -0.19 -0.12 0 -0 0</pose>
      <inertial>
        <pose frame=''>0 0 0.1 0 -0 0</pose>
        <mass>0.005</mass>
        <inertia>
          <ixx>9.75e-07</ixx>
          <ixy>0</ixy>
          <ixz>0</ixz>
          <iyy>4.17041e-05</iyy>
          <iyz>0</iyz>
          <izz>4.26041e-05</izz>
        </inertia>
      </inertial>
      <collision name='swift_pico/m4_collision'>
        <pose frame=''>0 0 0.1 0 -0 0</pose>
        <geometry>
          <cylinder>
            <length>0.005</length>
            <radius>0.1</radius>
          </cylinder>
        </geometry>
        <surface>
          <contact>
            <ode/>
          </contact>
          <friction>
            <ode/>
          </friction>
        </surface>
      </collision>
      <visual name='swift_pico/m4_visual'>
        <pose frame=''>0 0 0.1 0 -0 0</pose>
        <geometry>
          <mesh>
            <scale>5 5 5</scale>
            <uri>model://swift_pico/meshes/m4_link.dae</uri>
          </mesh>
        </geometry>
       <material>
          <ambient>1 1 0 1</ambient>
          <diffuse>1 1 0 1</diffuse>
          <specular>1 1 0 1</specular>
      </material>
      </visual>
      <gravity>1</gravity>
      <velocity_decay/>
    </link>
    <joint name='swift_pico/m4_joint' type='revolute'>
      <child>swift_pico/m4</child>
      <parent>swift_pico/base_link</parent>
      <axis>
        <xyz>0 0 1</xyz>
        <limit>
          <lower>-1e+16</lower>
          <upper>1e+16</upper>
        </limit>
        <dynamics>
          <spring_reference>0</spring_reference>
          <spring_stiffness>0</spring_stiffness>
        </dynamics>
        <use_parent_model_frame>1</use_parent_model_frame>
      </axis>
    </joint>
      <plugin
        filename="ignition-gazebo-multicopter-motor-model-system"
        name="gz::sim::systems::MulticopterMotorModel">
        <robotNamespace>rotors</robotNamespace>
        <jointName>swift_pico/m1_joint</jointName>
        <linkName>swift_pico/m1</linkName>
        <turningDirection>ccw</turningDirection>
        <timeConstantUp>0.0125</timeConstantUp>
        <timeConstantDown>0.025</timeConstantDown>
        <maxRotVelocity>800.0</maxRotVelocity>
        <motorConstant>8.54858e-06</motorConstant>
        <momentConstant>0.016</momentConstant>
        <commandSubTopic>command/motor_speed</commandSubTopic>
        <motorNumber>0</motorNumber>
        <rotorDragCoefficient>8.06428e-05</rotorDragCoefficient>
        <rollingMomentCoefficient>1e-06</rollingMomentCoefficient>
        <motorSpeedPubTopic>motor_speed/0</motorSpeedPubTopic>
        <rotorVelocitySlowdownSim>10</rotorVelocitySlowdownSim>
        <motorType>velocity</motorType>
      </plugin>
      <plugin
        filename="ignition-gazebo-multicopter-motor-model-system"
        name="gz::sim::systems::MulticopterMotorModel">
        <robotNamespace>rotors</robotNamespace>
        <jointName>swift_pico/m2_joint</jointName>
        <linkName>swift_pico/m2</linkName>
        <turningDirection>ccw</turningDirection>
        <timeConstantUp>0.0125</timeConstantUp>
        <timeConstantDown>0.025</timeConstantDown>
        <maxRotVelocity>800.0</maxRotVelocity>
        <motorConstant>8.54858e-06</motorConstant>
        <momentConstant>0.016</momentConstant>
        <commandSubTopic>command/motor_speed</commandSubTopic>
        <motorNumber>1</motorNumber>
        <rotorDragCoefficient>8.06428e-05</rotorDragCoefficient>
        <rollingMomentCoefficient>1e-06</rollingMomentCoefficient>
        <motorSpeedPubTopic>motor_speed/1</motorSpeedPubTopic>
        <rotorVelocitySlowdownSim>10</rotorVelocitySlowdownSim>
        <motorType>velocity</motorType>
      </plugin>
      <plugin
        filename="ignition-gazebo-multicopter-motor-model-system"
        name="gz::sim::systems::MulticopterMotorModel">
        <robotNamespace>rotors</robotNamespace>
        <jointName>swift_pico/m3_joint</jointName>
        <linkName>swift_pico/m3</linkName>
        <turningDirection>cw</turningDirection>
        <timeConstantUp>0.0125</timeConstantUp>
        <timeConstantDown>0.025</timeConstantDown>
        <maxRotVelocity>800.0</maxRotVelocity>
        <motorConstant>8.54858e-06</motorConstant>
        <momentConstant>0.016</momentConstant>
        <commandSubTopic>command/motor_speed</commandSubTopic>
        <motorNumber>2</motorNumber>
        <rotorDragCoefficient>8.06428e-05</rotorDragCoefficient>
        <rollingMomentCoefficient>1e-06</rollingMomentCoefficient>
        <motorSpeedPubTopic>motor_speed/2</motorSpeedPubTopic>
        <rotorVelocitySlowdownSim>10</rotorVelocitySlowdownSim>
        <motorType>velocity</motorType>
      </plugin>
      <plugin
        filename="ignition-gazebo-multicopter-motor-model-system"
        name="gz::sim::systems::MulticopterMotorModel">
        <robotNamespace>rotors</robotNamespace>
        <jointName>swift_pico/m4_joint</jointName>
        <linkName>swift_pico/m4</linkName>
        <turningDirection>cw</turningDirection>
        <timeConstantUp>0.0125</timeConstantUp>
        <timeConstantDown>0.025</timeConstantDown>
        <maxRotVelocity>800.0</maxRotVelocity>
        <motorConstant>8.54858e-06</motorConstant>
        <momentConstant>0.016</momentConstant>
        <commandSubTopic>command/motor_speed</commandSubTopic>
        <motorNumber>3</motorNumber>
        <rotorDragCoefficient>8.06428e-05</rotorDragCoefficient>
        <rollingMomentCoefficient>1e-06</rollingMomentCoefficient>
        <motorSpeedPubTopic>motor_speed/3</motorSpeedPubTopic>
        <rotorVelocitySlowdownSim>10</rotorVelocitySlowdownSim>
        <motorType>velocity</motorType>
      </plugin>
 
      <plugin
        filename="ignition-gazebo-odometry-publisher-system"
        name="ignition::gazebo::systems::OdometryPublisher">
        <dimensions>3</dimensions>
      </plugin>


  </model>
</sdf>